Workbook

Sheet Recorder
A1: Animal ID | B1: Arrow ID | C1: Scene | D1: Brain Area | E1: Label | F1: Field | G1: Stratum/Layer | H1: Additional Notes
B2: 448 | C2: 4 | D2: HPC | E2: Single PV | F2: CA1 | G2: S. Radiatum
B3: 447 | C3: 4 | D3: HPC | E3: Single PV | F3: CA2 | G3: S. Radiatum
B4: 446 | C4: 4 | D4: HPC | E4: Double | F4: CA1 | G4: S. Oriens
B5: 445 | C5: 4 | D5: HPC | E5: Double | F5: CA1 | G5: Pyramidal Layer
B6: 444 | C6: 4 | D6: HPC | E6: Double | F6: CA1 | G6: S. Oriens
B7: 443 | C7: 4 | D7: HPC | E7: Double | F7: CA1 | G7: Pyramidal Layer
B8: 442 | C8: 4 | D8: HPC | E8: Double | F8: CA1 | G8: Pyramidal Layer
B9: 441 | C9: 4 | D9: HPC | E9: Double | F9: CA1 | G9: Pyramidal Layer
B10: 440 | C10: 3 | D10: HPC | E10: Double | F10: CA3 | G10: S. Oriens
B11: 439 | C11: 3 | D11: HPC | E11: Double | F11: CA1 | G11: Pyramidal Layer
B12: 438 | C12: 3 | D12: HPC | E12: Double | F12: CA1 | G12: Pyramidal Layer
B13: 437 | C13: 3 | D13: HPC | E13: Double | F13: CA1 | G13: Pyramidal Layer
... B56: 394 | C56: 1 | D56: PFC | E56: Single PV | F56: PL | G56: PFC layers
B57: 393 | C57: section
B58: 392 | C58: section
B59: 391 | C59: 1 | D59: PFC | E59: Single PV | F59: PL | G59: PFC layers
A60: 58 | B60: 390 | C60: 4 | D60: HPC | E60: Single PV | F60: DG | G60: Granule Cell Layer
A61: 58 | B61: 389 | C61: 4 | D61: HPC | E61: Single PV | F61: DG | G61: Granule Cell Layer
A62: 58 | B62: 388 | C62: 4 | D62: HPC | E62: Double | F62: DG | G62: Granule Cell Layer
A63: 58 | B63: 387 | C63: 4 | D63: HPC | E63: Double | F63: DG | G63: Granule Cell Layer
A64: 58 | B64: 386 | C64: 4 | D64: HPC | E64: Double | F64: DG | G64: Granule Cell Layer
A65: 58 | B65: 385 | C65: 4 | D65: HPC | E65: Single PV | F65: DG | G65: Granule Cell Layer
A66: 58 | B66: 384 | C66: 4 | D66: HPC | E66: Single PV | F66: DG | G66: Granule Cell Layer
A67: 58 | B67: 383 | C67: 4 | D67: HPC | E67: Single PV | F67: DG | G67: Granule Cell Layer
A68: 58 | B68: 382 | C68: 4 | D68: HPC | E68: Single PV | F68: DG | G68: Granule Cell Layer
A69: 58 | B69: 381 | C69: 4 | D69: HPC | E69: Single PV | F69: DG | G69: Granule Cell Layer
A70: 58 | B70: 380 | C70: 4 | D70: HPC | E70: Double | F70: DG | G70: Granule Cell Layer
A71: 58 | B71: 379 | C71: 4 | D71: HPC | E71: Single PV | F71: DG | G71: Granule Cell Layer
... A436: 58 | B436: 14 | C436: 1 | D436: PFC | E436: Single PV | F436: PL | G436: PFC layers
A438: MAKE A COPY OF THIS SPREADSHEET AND NAME IT "##_UCB Age Cell Counting"

Sheet Analysis
A2: Animal ID | B2: 58
A4: HPC
A5: CA1 | B5: S. Oriens | C5: Pyramidal Layer | D5: S. Radiatum | E5: S. Lucidum | F5: S. Lacunosum-moleculare | G5: Molecular Layer | H5: Polymorph Layer | I5: Granule Cell Layer | J5: FC layer | K5: Total
A6: Double | B6: =COUNTIFS(Recorder!$A:$A,$B$2,Recorder!$E:$E,$A6,Recorder!$G:$G,B$5,Recorder!$F:$F,$A$5,Recorder!$D:$D,$A$4) -> 22 | C6: =COUNTIFS(Recorder!$A:$A,$B$2,Recorder!$E:$E,$A6,Recorder!$G:$G,C$5,Recorder!$F:$F,$A$5,Recorder!$D:$D,$A$4) -> 24 | D6: =COUNTIFS(Recorder!$A:$A,$B$2,Recorder!$E:$E,$A6,Recorder!$G:$G,D$5,Recorder!$F:$F,$A$5,Recorder!$D:$D,$A$4) -> 3 | E6: =COUNTIFS(Recorder!$A:$A,$B$2,Recorder!$E:$E,$A6,Recorder!$G:$G,E$5,Recorder!$F:$F,$A$5,Recorder!$D:$D,$A$4) -> 0 | F6: =COUNTIFS(Recorder!$A:$A,$B$2,Recorder!$E:$E,$A6,Recorder!$G:$G,F$5,Recorder!$F:$F,$A$5,Recorder!$D:$D,$A$4) -> 0 | G6: =COUNTIFS(Recorder!$A:$A,$B$2,Recorder!$E:$E,$A6,Recorder!$G:$G,G$5,Recorder!$F:$F,$A$5,Recorder!$D:$D,$A$4) -> 0 | H6: =COUNTIFS(Recorder!$A:$A,$B$2,Recorder!$E:$E,$A6,Recorder!$G:$G,H$5,Recorder!$F:$F,$A$5,Recorder!$D:$D,$A$4) -> 0 | I6: =COUNTIFS(Recorder!$A:$A,$B$2,Recorder!$E:$E,$A6,Recorder!$G:$G,I$5,Recorder!$F:$F,$A$5,Recorder!$D:$D,$A$4) -> 0 | J6: =COUNTIFS(Recorder!$A:$A,$B$2,Recorder!$E:$E,$A6,Recorder!$G:$G,J$5,Recorder!$F:$F,$A$5,Recorder!$D:$D,$A$4) -> 0 | K6: =SUM(B6:J6) -> 49
A7: Single PV | B7: =COUNTIFS(Recorder!$A:$A,$B$2,Recorder!$E:$E,$A7,Recorder!$G:$G,B$5,Recorder!$F:$F,$A$5,Recorder!$D:$D,$A$4) -> 8 | C7: =COUNTIFS(Recorder!$A:$A,$B$2,Recorder!$E:$E,$A7,Recorder!$G:$G,C$5,Recorder!$F:$F,$A$5,Recorder!$D:$D,$A$4) -> 17 | D7: =COUNTIFS(Recorder!$A:$A,$B$2,Recorder!$E:$E,$A7,Recorder!$G:$G,D$5,Recorder!$F:$F,$A$5,Recorder!$D:$D,$A$4) -> 1 | E7: =COUNTIFS(Recorder!$A:$A,$B$2,Recorder!$E:$E,$A7,Recorder!$G:$G,E$5,Recorder!$F:$F,$A$5,Recorder!$D:$D,$A$4) -> 0 | F7: =COUNTIFS(Recorder!$A:$A,$B$2,Recorder!$E:$E,$A7,Recorder!$G:$G,F$5,Recorder!$F:$F,$A$5,Recorder!$D:$D,$A$4) -> 0 | G7: =COUNTIFS(Recorder!$A:$A,$B$2,Recorder!$E:$E,$A7,Recorder!$G:$G,G$5,Recorder!$F:$F,$A$5,Recorder!$D:$D,$A$4) -> 0 | H7: =COUNTIFS(Recorder!$A:$A,$B$2,Recorder!$E:$E,$A7,Recorder!$G:$G,H$5,Recorder!$F:$F,$A$5,Recorder!$D:$D,$A$4) -> 0 | I7: =COUNTIFS(Recorder!$A:$A,$B$2,Recorder!$E:$E,$A7,Recorder!$G:$G,I$5,Recorder!$F:$F,$A$5,Recorder!$D:$D,$A$4) -> 0 | J7: =COUNTIFS(Recorder!$A:$A,$B$2,Recorder!$E:$E,$A7,Recorder!$G:$G,J$5,Recorder!$F:$F,$A$5,Recorder!$D:$D,$A$4) -> 0 | K7: =SUM(B7:J7) -> 26
A8: Unsure | B8: =COUNTIFS(Recorder!$A:$A,$B$2,Recorder!$E:$E,$A8,Recorder!$G:$G,B$5,Recorder!$F:$F,$A$5,Recorder!$D:$D,$A$4) -> 0 | C8: =COUNTIFS(Recorder!$A:$A,$B$2,Recorder!$E:$E,$A8,Recorder!$G:$G,C$5,Recorder!$F:$F,$A$5,Recorder!$D:$D,$A$4) -> 0 | D8: =COUNTIFS(Recorder!$A:$A,$B$2,Recorder!$E:$E,$A8,Recorder!$G:$G,D$5,Recorder!$F:$F,$A$5,Recorder!$D:$D,$A$4) -> 0 | E8: =COUNTIFS(Recorder!$A:$A,$B$2,Recorder!$E:$E,$A8,Recorder!$G:$G,E$5,Recorder!$F:$F,$A$5,Recorder!$D:$D,$A$4) -> 0 | F8: =COUNTIFS(Recorder!$A:$A,$B$2,Recorder!$E:$E,$A8,Recorder!$G:$G,F$5,Recorder!$F:$F,$A$5,Recorder!$D:$D,$A$4) -> 0 | G8: =COUNTIFS(Recorder!$A:$A,$B$2,Recorder!$E:$E,$A8,Recorder!$G:$G,G$5,Recorder!$F:$F,$A$5,Recorder!$D:$D,$A$4) -> 0 | H8: =COUNTIFS(Recorder!$A:$A,$B$2,Recorder!$E:$E,$A8,Recorder!$G:$G,H$5,Recorder!$F:$F,$A$5,Recorder!$D:$D,$A$4) -> 0 | I8: =COUNTIFS(Recorder!$A:$A,$B$2,Recorder!$E:$E,$A8,Recorder!$G:$G,I$5,Recorder!$F:$F,$A$5,Recorder!$D:$D,$A$4) -> 0 | J8: =COUNTIFS(Recorder!$A:$A,$B$2,Recorder!$E:$E,$A8,Recorder!$G:$G,J$5,Recorder!$F:$F,$A$5,Recorder!$D:$D,$A$4) -> 0 | K8: =SUM(B8:J8) -> 0
A9: Total | B9: =SUM(B6:B8) -> 30 | C9: =SUM(C6:C8) -> 41 | D9: =SUM(D6:D8) -> 4 | E9: =SUM(E6:E8) -> 0 | F9: =SUM(F6:F8) -> 0 | G9: =SUM(G6:G8) -> 0 | H9: =SUM(H6:H8) -> 0 | I9: =SUM(I6:I8) -> 0 | ... K9: =SUM(K6:K8) -> 75
A11: HPC
A12: CA2 | B12: S. Oriens | C12: Pyramidal Layer | D12: S. Radiatum | E12: S. Lucidum | F12: S. Lacunosum-moleculare | G12: Molecular Layer | H12: Polymorph Layer | I12: Granule Cell Layer | J12: FC layer | K12: Total
A13: Double | B13: =COUNTIFS(Recorder!$A:$A,$B$2,Recorder!$E:$E,$A13,Recorder!$G:$G,B$5,Recorder!$F:$F,$A$12,Recorder!$D:$D,$A$11) -> 3 | C13: =COUNTIFS(Recorder!$A:$A,$B$2,Recorder!$E:$E,$A13,Recorder!$G:$G,C$5,Recorder!$F:$F,$A$12,Recorder!$D:$D,$A$11) -> 8 | D13: =COUNTIFS(Recorder!$A:$A,$B$2,Recorder!$E:$E,$A13,Recorder!$G:$G,D$5,Recorder!$F:$F,$A$12,Recorder!$D:$D,$A$11) -> 0 | E13: =COUNTIFS(Recorder!$A:$A,$B$2,Recorder!$E:$E,$A13,Recorder!$G:$G,E$5,Recorder!$F:$F,$A$12,Recorder!$D:$D,$A$11) -> 0 | F13: =COUNTIFS(Recorder!$A:$A,$B$2,Recorder!$E:$E,$A13,Recorder!$G:$G,F$5,Recorder!$F:$F,$A$12,Recorder!$D:$D,$A$11) -> 0 | G13: =COUNTIFS(Recorder!$A:$A,$B$2,Recorder!$E:$E,$A13,Recorder!$G:$G,G$5,Recorder!$F:$F,$A$12,Recorder!$D:$D,$A$11) -> 0 | H13: =COUNTIFS(Recorder!$A:$A,$B$2,Recorder!$E:$E,$A13,Recorder!$G:$G,H$5,Recorder!$F:$F,$A$12,Recorder!$D:$D,$A$11) -> 0 | I13: =COUNTIFS(Recorder!$A:$A,$B$2,Recorder!$E:$E,$A13,Recorder!$G:$G,I$5,Recorder!$F:$F,$A$12,Recorder!$D:$D,$A$11) -> 0 | J13: =COUNTIFS(Recorder!$A:$A,$B$2,Recorder!$E:$E,$A13,Recorder!$G:$G,J$5,Recorder!$F:$F,$A$12,Recorder!$D:$D,$A$11) -> 0 | K13: =SUM(B13:J13) -> 11
A14: Single PV | B14: =COUNTIFS(Recorder!$A:$A,$B$2,Recorder!$E:$E,$A14,Recorder!$G:$G,B$5,Recorder!$F:$F,$A$12,Recorder!$D:$D,$A$11) -> 2 | C14: =COUNTIFS(Recorder!$A:$A,$B$2,Recorder!$E:$E,$A14,Recorder!$G:$G,C$5,Recorder!$F:$F,$A$12,Recorder!$D:$D,$A$11) -> 5 | D14: =COUNTIFS(Recorder!$A:$A,$B$2,Recorder!$E:$E,$A14,Recorder!$G:$G,D$5,Recorder!$F:$F,$A$12,Recorder!$D:$D,$A$11) -> 1 | E14: =COUNTIFS(Recorder!$A:$A,$B$2,Recorder!$E:$E,$A14,Recorder!$G:$G,E$5,Recorder!$F:$F,$A$12,Recorder!$D:$D,$A$11) -> 0 | F14: =COUNTIFS(Recorder!$A:$A,$B$2,Recorder!$E:$E,$A14,Recorder!$G:$G,F$5,Recorder!$F:$F,$A$12,Recorder!$D:$D,$A$11) -> 0 | G14: =COUNTIFS(Recorder!$A:$A,$B$2,Recorder!$E:$E,$A14,Recorder!$G:$G,G$5,Recorder!$F:$F,$A$12,Recorder!$D:$D,$A$11) -> 0 | H14: =COUNTIFS(Recorder!$A:$A,$B$2,Recorder!$E:$E,$A14,Recorder!$G:$G,H$5,Recorder!$F:$F,$A$12,Recorder!$D:$D,$A$11) -> 0 | I14: =COUNTIFS(Recorder!$A:$A,$B$2,Recorder!$E:$E,$A14,Recorder!$G:$G,I$5,Recorder!$F:$F,$A$12,Recorder!$D:$D,$A$11) -> 0 | J14: =COUNTIFS(Recorder!$A:$A,$B$2,Recorder!$E:$E,$A14,Recorder!$G:$G,J$5,Recorder!$F:$F,$A$12,Recorder!$D:$D,$A$11) -> 0 | K14: =SUM(B14:J14) -> 8
A15: Unsure | B15: =COUNTIFS(Recorder!$A:$A,$B$2,Recorder!$E:$E,$A15,Recorder!$G:$G,B$5,Recorder!$F:$F,$A$12,Recorder!$D:$D,$A$11) -> 0 | C15: =COUNTIFS(Recorder!$A:$A,$B$2,Recorder!$E:$E,$A15,Recorder!$G:$G,C$5,Recorder!$F:$F,$A$12,Recorder!$D:$D,$A$11) -> 0 | D15: =COUNTIFS(Recorder!$A:$A,$B$2,Recorder!$E:$E,$A15,Recorder!$G:$G,D$5,Recorder!$F:$F,$A$12,Recorder!$D:$D,$A$11) -> 0 | E15: =COUNTIFS(Recorder!$A:$A,$B$2,Recorder!$E:$E,$A15,Recorder!$G:$G,E$5,Recorder!$F:$F,$A$12,Recorder!$D:$D,$A$11) -> 0 | F15: =COUNTIFS(Recorder!$A:$A,$B$2,Recorder!$E:$E,$A15,Recorder!$G:$G,F$5,Recorder!$F:$F,$A$12,Recorder!$D:$D,$A$11) -> 0 | G15: =COUNTIFS(Recorder!$A:$A,$B$2,Recorder!$E:$E,$A15,Recorder!$G:$G,G$5,Recorder!$F:$F,$A$12,Recorder!$D:$D,$A$11) -> 0 | H15: =COUNTIFS(Recorder!$A:$A,$B$2,Recorder!$E:$E,$A15,Recorder!$G:$G,H$5,Recorder!$F:$F,$A$12,Recorder!$D:$D,$A$11) -> 0 | I15: =COUNTIFS(Recorder!$A:$A,$B$2,Recorder!$E:$E,$A15,Recorder!$G:$G,I$5,Recorder!$F:$F,$A$12,Recorder!$D:$D,$A$11) -> 0 | J15: =COUNTIFS(Recorder!$A:$A,$B$2,Recorder!$E:$E,$A15,Recorder!$G:$G,J$5,Recorder!$F:$F,$A$12,Recorder!$D:$D,$A$11) -> 0 | K15: =SUM(B15:J15) -> 0
A16: Total | B16: =SUM(B13:B15) -> 5 | C16: =SUM(C13:C15) -> 13 | D16: =SUM(D13:D15) -> 1 | E16: =SUM(E13:E15) -> 0 | F16: =SUM(F13:F15) -> 0 | G16: =SUM(G13:G15) -> 0 | H16: =SUM(H13:H15) -> 0 | I16: =SUM(I13:I15) -> 0 | ... K16: =SUM(K13:K15) -> 19
A18: HPC
A19: CA3 | B19: S. Oriens | C19: Pyramidal Layer | D19: S. Radiatum | E19: S. Lucidum | F19: S. Lacunosum-moleculare | G19: Molecular Layer | H19: Polymorph Layer | I19: Granule Cell Layer | J19: FC layer | K19: Total
A20: Double | B20: =COUNTIFS(Recorder!$A:$A,$B$2,Recorder!$E:$E,$A20,Recorder!$G:$G,B$5,Recorder!$F:$F,$A$19,Recorder!$D:$D,$A$18) -> 2 | C20: =COUNTIFS(Recorder!$A:$A,$B$2,Recorder!$E:$E,$A20,Recorder!$G:$G,C$5,Recorder!$F:$F,$A$19,Recorder!$D:$D,$A$18) -> 4 | D20: =COUNTIFS(Recorder!$A:$A,$B$2,Recorder!$E:$E,$A20,Recorder!$G:$G,D$5,Recorder!$F:$F,$A$19,Recorder!$D:$D,$A$18) -> 2 | E20: =COUNTIFS(Recorder!$A:$A,$B$2,Recorder!$E:$E,$A20,Recorder!$G:$G,E$5,Recorder!$F:$F,$A$19,Recorder!$D:$D,$A$18) -> 2 | F20: =COUNTIFS(Recorder!$A:$A,$B$2,Recorder!$E:$E,$A20,Recorder!$G:$G,F$5,Recorder!$F:$F,$A$19,Recorder!$D:$D,$A$18) -> 0 | G20: =COUNTIFS(Recorder!$A:$A,$B$2,Recorder!$E:$E,$A20,Recorder!$G:$G,G$5,Recorder!$F:$F,$A$19,Recorder!$D:$D,$A$18) -> 0 | H20: =COUNTIFS(Recorder!$A:$A,$B$2,Recorder!$E:$E,$A20,Recorder!$G:$G,H$5,Recorder!$F:$F,$A$19,Recorder!$D:$D,$A$18) -> 0 | I20: =COUNTIFS(Recorder!$A:$A,$B$2,Recorder!$E:$E,$A20,Recorder!$G:$G,I$5,Recorder!$F:$F,$A$19,Recorder!$D:$D,$A$18) -> 0 | J20: =COUNTIFS(Recorder!$A:$A,$B$2,Recorder!$E:$E,$A20,Recorder!$G:$G,J$5,Recorder!$F:$F,$A$19,Recorder!$D:$D,$A$18) -> 0 | K20: =SUM(B20:J20) -> 10
A21: Single PV | B21: =COUNTIFS(Recorder!$A:$A,$B$2,Recorder!$E:$E,$A21,Recorder!$G:$G,B$5,Recorder!$F:$F,$A$19,Recorder!$D:$D,$A$18) -> 7 | C21: =COUNTIFS(Recorder!$A:$A,$B$2,Recorder!$E:$E,$A21,Recorder!$G:$G,C$5,Recorder!$F:$F,$A$19,Recorder!$D:$D,$A$18) -> 18 | D21: =COUNTIFS(Recorder!$A:$A,$B$2,Recorder!$E:$E,$A21,Recorder!$G:$G,D$5,Recorder!$F:$F,$A$19,Recorder!$D:$D,$A$18) -> 1 | E21: =COUNTIFS(Recorder!$A:$A,$B$2,Recorder!$E:$E,$A21,Recorder!$G:$G,E$5,Recorder!$F:$F,$A$19,Recorder!$D:$D,$A$18) -> 3 | F21: =COUNTIFS(Recorder!$A:$A,$B$2,Recorder!$E:$E,$A21,Recorder!$G:$G,F$5,Recorder!$F:$F,$A$19,Recorder!$D:$D,$A$18) -> 0 | G21: =COUNTIFS(Recorder!$A:$A,$B$2,Recorder!$E:$E,$A21,Recorder!$G:$G,G$5,Recorder!$F:$F,$A$19,Recorder!$D:$D,$A$18) -> 0 | H21: =COUNTIFS(Recorder!$A:$A,$B$2,Recorder!$E:$E,$A21,Recorder!$G:$G,H$5,Recorder!$F:$F,$A$19,Recorder!$D:$D,$A$18) -> 0 | I21: =COUNTIFS(Recorder!$A:$A,$B$2,Recorder!$E:$E,$A21,Recorder!$G:$G,I$5,Recorder!$F:$F,$A$19,Recorder!$D:$D,$A$18) -> 0 | J21: =COUNTIFS(Recorder!$A:$A,$B$2,Recorder!$E:$E,$A21,Recorder!$G:$G,J$5,Recorder!$F:$F,$A$19,Recorder!$D:$D,$A$18) -> 0 | K21: =SUM(B21:J21) -> 29
A22: Unsure | B22: =COUNTIFS(Recorder!$A:$A,$B$2,Recorder!$E:$E,$A22,Recorder!$G:$G,B$5,Recorder!$F:$F,$A$19,Recorder!$D:$D,$A$18) -> 0 | C22: =COUNTIFS(Recorder!$A:$A,$B$2,Recorder!$E:$E,$A22,Recorder!$G:$G,C$5,Recorder!$F:$F,$A$19,Recorder!$D:$D,$A$18) -> 0 | D22: =COUNTIFS(Recorder!$A:$A,$B$2,Recorder!$E:$E,$A22,Recorder!$G:$G,D$5,Recorder!$F:$F,$A$19,Recorder!$D:$D,$A$18) -> 0 | E22: =COUNTIFS(Recorder!$A:$A,$B$2,Recorder!$E:$E,$A22,Recorder!$G:$G,E$5,Recorder!$F:$F,$A$19,Recorder!$D:$D,$A$18) -> 0 | F22: =COUNTIFS(Recorder!$A:$A,$B$2,Recorder!$E:$E,$A22,Recorder!$G:$G,F$5,Recorder!$F:$F,$A$19,Recorder!$D:$D,$A$18) -> 0 | G22: =COUNTIFS(Recorder!$A:$A,$B$2,Recorder!$E:$E,$A22,Recorder!$G:$G,G$5,Recorder!$F:$F,$A$19,Recorder!$D:$D,$A$18) -> 0 | H22: =COUNTIFS(Recorder!$A:$A,$B$2,Recorder!$E:$E,$A22,Recorder!$G:$G,H$5,Recorder!$F:$F,$A$19,Recorder!$D:$D,$A$18) -> 0 | I22: =COUNTIFS(Recorder!$A:$A,$B$2,Recorder!$E:$E,$A22,Recorder!$G:$G,I$5,Recorder!$F:$F,$A$19,Recorder!$D:$D,$A$18) -> 0 | J22: =COUNTIFS(Recorder!$A:$A,$B$2,Recorder!$E:$E,$A22,Recorder!$G:$G,J$5,Recorder!$F:$F,$A$19,Recorder!$D:$D,$A$18) -> 0 | K22: =SUM(B22:J22) -> 0
A23: Total | B23: =SUM(B20:B22) -> 9 | C23: =SUM(C20:C22) -> 22 | D23: =SUM(D20:D22) -> 3 | E23: =SUM(E20:E22) -> 5 | F23: =SUM(F20:F22) -> 0 | G23: =SUM(G20:G22) -> 0 | H23: =SUM(H20:H22) -> 0 | I23: =SUM(I20:I22) -> 0 | ... K23: =SUM(K20:K22) -> 39
A25: HPC
A26: DG | B26: S. Oriens | C26: Pyramidal Layer | D26: S. Radiatum | E26: S. Lucidum | F26: S. Lacunosum-moleculare | G26: Molecular Layer | H26: Polymorph Layer | I26: Granule Cell Layer | J26: FC layer | K26: Total
A27: Double | B27: =COUNTIFS(Recorder!$A:$A,$B$2,Recorder!$E:$E,$A27,Recorder!$G:$G,B$5,Recorder!$F:$F,$A$26,Recorder!$D:$D,$A$25) -> 0 | C27: =COUNTIFS(Recorder!$A:$A,$B$2,Recorder!$E:$E,$A27,Recorder!$G:$G,C$5,Recorder!$F:$F,$A$26,Recorder!$D:$D,$A$25) -> 0 | D27: =COUNTIFS(Recorder!$A:$A,$B$2,Recorder!$E:$E,$A27,Recorder!$G:$G,D$5,Recorder!$F:$F,$A$26,Recorder!$D:$D,$A$25) -> 0 | E27: =COUNTIFS(Recorder!$A:$A,$B$2,Recorder!$E:$E,$A27,Recorder!$G:$G,E$5,Recorder!$F:$F,$A$26,Recorder!$D:$D,$A$25) -> 0 | F27: =COUNTIFS(Recorder!$A:$A,$B$2,Recorder!$E:$E,$A27,Recorder!$G:$G,F$5,Recorder!$F:$F,$A$26,Recorder!$D:$D,$A$25) -> 0 | G27: =COUNTIFS(Recorder!$A:$A,$B$2,Recorder!$E:$E,$A27,Recorder!$G:$G,G$5,Recorder!$F:$F,$A$26,Recorder!$D:$D,$A$25) -> 0 | H27: =COUNTIFS(Recorder!$A:$A,$B$2,Recorder!$E:$E,$A27,Recorder!$G:$G,H$5,Recorder!$F:$F,$A$26,Recorder!$D:$D,$A$25) -> 1 | I27: =COUNTIFS(Recorder!$A:$A,$B$2,Recorder!$E:$E,$A27,Recorder!$G:$G,I$5,Recorder!$F:$F,$A$26,Recorder!$D:$D,$A$25) -> 11 | J27: =COUNTIFS(Recorder!$A:$A,$B$2,Recorder!$E:$E,$A27,Recorder!$G:$G,J$5,Recorder!$F:$F,$A$26,Recorder!$D:$D,$A$25) -> 0 | K27: =SUM(B27:J27) -> 12
A28: Single PV | B28: =COUNTIFS(Recorder!$A:$A,$B$2,Recorder!$E:$E,$A28,Recorder!$G:$G,B$5,Recorder!$F:$F,$A$26,Recorder!$D:$D,$A$25) -> 0 | C28: =COUNTIFS(Recorder!$A:$A,$B$2,Recorder!$E:$E,$A28,Recorder!$G:$G,C$5,Recorder!$F:$F,$A$26,Recorder!$D:$D,$A$25) -> 0 | D28: =COUNTIFS(Recorder!$A:$A,$B$2,Recorder!$E:$E,$A28,Recorder!$G:$G,D$5,Recorder!$F:$F,$A$26,Recorder!$D:$D,$A$25) -> 0 | E28: =COUNTIFS(Recorder!$A:$A,$B$2,Recorder!$E:$E,$A28,Recorder!$G:$G,E$5,Recorder!$F:$F,$A$26,Recorder!$D:$D,$A$25) -> 0 | F28: =COUNTIFS(Recorder!$A:$A,$B$2,Recorder!$E:$E,$A28,Recorder!$G:$G,F$5,Recorder!$F:$F,$A$26,Recorder!$D:$D,$A$25) -> 0 | G28: =COUNTIFS(Recorder!$A:$A,$B$2,Recorder!$E:$E,$A28,Recorder!$G:$G,G$5,Recorder!$F:$F,$A$26,Recorder!$D:$D,$A$25) -> 0 | H28: =COUNTIFS(Recorder!$A:$A,$B$2,Recorder!$E:$E,$A28,Recorder!$G:$G,H$5,Recorder!$F:$F,$A$26,Recorder!$D:$D,$A$25) -> 0 | I28: =COUNTIFS(Recorder!$A:$A,$B$2,Recorder!$E:$E,$A28,Recorder!$G:$G,I$5,Recorder!$F:$F,$A$26,Recorder!$D:$D,$A$25) -> 14 | J28: =COUNTIFS(Recorder!$A:$A,$B$2,Recorder!$E:$E,$A28,Recorder!$G:$G,J$5,Recorder!$F:$F,$A$26,Recorder!$D:$D,$A$25) -> 0 | K28: =SUM(B28:J28) -> 14
A29: Unsure | B29: =COUNTIFS(Recorder!$A:$A,$B$2,Recorder!$E:$E,$A29,Recorder!$G:$G,B$5,Recorder!$F:$F,$A$26,Recorder!$D:$D,$A$25) -> 0 | C29: =COUNTIFS(Recorder!$A:$A,$B$2,Recorder!$E:$E,$A29,Recorder!$G:$G,C$5,Recorder!$F:$F,$A$26,Recorder!$D:$D,$A$25) -> 0 | D29: =COUNTIFS(Recorder!$A:$A,$B$2,Recorder!$E:$E,$A29,Recorder!$G:$G,D$5,Recorder!$F:$F,$A$26,Recorder!$D:$D,$A$25) -> 0 | E29: =COUNTIFS(Recorder!$A:$A,$B$2,Recorder!$E:$E,$A29,Recorder!$G:$G,E$5,Recorder!$F:$F,$A$26,Recorder!$D:$D,$A$25) -> 0 | F29: =COUNTIFS(Recorder!$A:$A,$B$2,Recorder!$E:$E,$A29,Recorder!$G:$G,F$5,Recorder!$F:$F,$A$26,Recorder!$D:$D,$A$25) -> 0 | G29: =COUNTIFS(Recorder!$A:$A,$B$2,Recorder!$E:$E,$A29,Recorder!$G:$G,G$5,Recorder!$F:$F,$A$26,Recorder!$D:$D,$A$25) -> 0 | H29: =COUNTIFS(Recorder!$A:$A,$B$2,Recorder!$E:$E,$A29,Recorder!$G:$G,H$5,Recorder!$F:$F,$A$26,Recorder!$D:$D,$A$25) -> 0 | I29: =COUNTIFS(Recorder!$A:$A,$B$2,Recorder!$E:$E,$A29,Recorder!$G:$G,I$5,Recorder!$F:$F,$A$26,Recorder!$D:$D,$A$25) -> 0 | J29: =COUNTIFS(Recorder!$A:$A,$B$2,Recorder!$E:$E,$A29,Recorder!$G:$G,J$5,Recorder!$F:$F,$A$26,Recorder!$D:$D,$A$25) -> 0 | K29: =SUM(B29:J29) -> 0
A30: Total | B30: =SUM(B27:B29) -> 0 | C30: =SUM(C27:C29) -> 0 | D30: =SUM(D27:D29) -> 0 | E30: =SUM(E27:E29) -> 0 | F30: =SUM(F27:F29) -> 0 | G30: =SUM(G27:G29) -> 0 | H30: =SUM(H27:H29) -> 1 | I30: =SUM(I27:I29) -> 25 | ... K30: =SUM(K27:K29) -> 26
A32: HPC
A33: Fasciola Cinerea | B33: S. Oriens | C33: Pyramidal Layer | D33: S. Radiatum | E33: S. Lucidum | F33: S. Lacunosum-moleculare | G33: Molecular Layer | H33: Polymorph Layer | I33: Granule Cell Layer | J33: FC layer | K33: Total
A34: Double | B34: =COUNTIFS(Recorder!$A:$A,$B$2,Recorder!$E:$E,$A34,Recorder!$G:$G,B$5,Recorder!$F:$F,$A$33,Recorder!$D:$D,$A$32) -> 0 | C34: =COUNTIFS(Recorder!$A:$A,$B$2,Recorder!$E:$E,$A34,Recorder!$G:$G,C$5,Recorder!$F:$F,$A$33,Recorder!$D:$D,$A$32) -> 0 | D34: =COUNTIFS(Recorder!$A:$A,$B$2,Recorder!$E:$E,$A34,Recorder!$G:$G,D$5,Recorder!$F:$F,$A$33,Recorder!$D:$D,$A$32) -> 0 | E34: =COUNTIFS(Recorder!$A:$A,$B$2,Recorder!$E:$E,$A34,Recorder!$G:$G,E$5,Recorder!$F:$F,$A$33,Recorder!$D:$D,$A$32) -> 0 | F34: =COUNTIFS(Recorder!$A:$A,$B$2,Recorder!$E:$E,$A34,Recorder!$G:$G,F$5,Recorder!$F:$F,$A$33,Recorder!$D:$D,$A$32) -> 0 | G34: =COUNTIFS(Recorder!$A:$A,$B$2,Recorder!$E:$E,$A34,Recorder!$G:$G,G$5,Recorder!$F:$F,$A$33,Recorder!$D:$D,$A$32) -> 0 | H34: =COUNTIFS(Recorder!$A:$A,$B$2,Recorder!$E:$E,$A34,Recorder!$G:$G,H$5,Recorder!$F:$F,$A$33,Recorder!$D:$D,$A$32) -> 0 | I34: =COUNTIFS(Recorder!$A:$A,$B$2,Recorder!$E:$E,$A34,Recorder!$G:$G,I$5,Recorder!$F:$F,$A$33,Recorder!$D:$D,$A$32) -> 0 | J34: =COUNTIFS(Recorder!$A:$A,$B$2,Recorder!$E:$E,$A34,Recorder!$G:$G,J$5,Recorder!$F:$F,$A$33,Recorder!$D:$D,$A$32) -> 1 | K34: =SUM(B34:J34) -> 1
A35: Single PV | B35: =COUNTIFS(Recorder!$A:$A,$B$2,Recorder!$E:$E,$A35,Recorder!$G:$G,B$5,Recorder!$F:$F,$A$33,Recorder!$D:$D,$A$32) -> 0 | C35: =COUNTIFS(Recorder!$A:$A,$B$2,Recorder!$E:$E,$A35,Recorder!$G:$G,C$5,Recorder!$F:$F,$A$33,Recorder!$D:$D,$A$32) -> 0 | D35: =COUNTIFS(Recorder!$A:$A,$B$2,Recorder!$E:$E,$A35,Recorder!$G:$G,D$5,Recorder!$F:$F,$A$33,Recorder!$D:$D,$A$32) -> 0 | E35: =COUNTIFS(Recorder!$A:$A,$B$2,Recorder!$E:$E,$A35,Recorder!$G:$G,E$5,Recorder!$F:$F,$A$33,Recorder!$D:$D,$A$32) -> 0 | F35: =COUNTIFS(Recorder!$A:$A,$B$2,Recorder!$E:$E,$A35,Recorder!$G:$G,F$5,Recorder!$F:$F,$A$33,Recorder!$D:$D,$A$32) -> 0 | G35: =COUNTIFS(Recorder!$A:$A,$B$2,Recorder!$E:$E,$A35,Recorder!$G:$G,G$5,Recorder!$F:$F,$A$33,Recorder!$D:$D,$A$32) -> 0 | H35: =COUNTIFS(Recorder!$A:$A,$B$2,Recorder!$E:$E,$A35,Recorder!$G:$G,H$5,Recorder!$F:$F,$A$33,Recorder!$D:$D,$A$32) -> 0 | I35: =COUNTIFS(Recorder!$A:$A,$B$2,Recorder!$E:$E,$A35,Recorder!$G:$G,I$5,Recorder!$F:$F,$A$33,Recorder!$D:$D,$A$32) -> 0 | J35: =COUNTIFS(Recorder!$A:$A,$B$2,Recorder!$E:$E,$A35,Recorder!$G:$G,J$5,Recorder!$F:$F,$A$33,Recorder!$D:$D,$A$32) -> 8 | K35: =SUM(B35:J35) -> 8
A36: Unsure | B36: =COUNTIFS(Recorder!$A:$A,$B$2,Recorder!$E:$E,$A36,Recorder!$G:$G,B$5,Recorder!$F:$F,$A$33,Recorder!$D:$D,$A$32) -> 0 | C36: =COUNTIFS(Recorder!$A:$A,$B$2,Recorder!$E:$E,$A36,Recorder!$G:$G,C$5,Recorder!$F:$F,$A$33,Recorder!$D:$D,$A$32) -> 0 | D36: =COUNTIFS(Recorder!$A:$A,$B$2,Recorder!$E:$E,$A36,Recorder!$G:$G,D$5,Recorder!$F:$F,$A$33,Recorder!$D:$D,$A$32) -> 0 | E36: =COUNTIFS(Recorder!$A:$A,$B$2,Recorder!$E:$E,$A36,Recorder!$G:$G,E$5,Recorder!$F:$F,$A$33,Recorder!$D:$D,$A$32) -> 0 | F36: =COUNTIFS(Recorder!$A:$A,$B$2,Recorder!$E:$E,$A36,Recorder!$G:$G,F$5,Recorder!$F:$F,$A$33,Recorder!$D:$D,$A$32) -> 0 | G36: =COUNTIFS(Recorder!$A:$A,$B$2,Recorder!$E:$E,$A36,Recorder!$G:$G,G$5,Recorder!$F:$F,$A$33,Recorder!$D:$D,$A$32) -> 0 | H36: =COUNTIFS(Recorder!$A:$A,$B$2,Recorder!$E:$E,$A36,Recorder!$G:$G,H$5,Recorder!$F:$F,$A$33,Recorder!$D:$D,$A$32) -> 0 | I36: =COUNTIFS(Recorder!$A:$A,$B$2,Recorder!$E:$E,$A36,Recorder!$G:$G,I$5,Recorder!$F:$F,$A$33,Recorder!$D:$D,$A$32) -> 0 | J36: =COUNTIFS(Recorder!$A:$A,$B$2,Recorder!$E:$E,$A36,Recorder!$G:$G,J$5,Recorder!$F:$F,$A$33,Recorder!$D:$D,$A$32) -> 0 | K36: =SUM(B36:J36) -> 0
A37: Total | B37: =SUM(B34:B36) -> 0 | C37: =SUM(C34:C36) -> 0 | D37: =SUM(D34:D36) -> 0 | E37: =SUM(E34:E36) -> 0 | F37: =SUM(F34:F36) -> 0 | G37: =SUM(G34:G36) -> 0 | H37: =SUM(H34:H36) -> 0 | I37: =SUM(I34:I36) -> 0 | ... K37: =SUM(K34:K36) -> 9
A39: PFC
A40: AC | B40: PFC layers | C40: Total
A41: Double | B41: =COUNTIFS(Recorder!$A:$A,$B$2,Recorder!$E:$E,$A41,Recorder!$G:$G,B$40,Recorder!$F:$F,$A$40,Recorder!$D:$D,$A$39) -> 0 | C41: =SUM(B41) -> 0
A42: Single PV | B42: =COUNTIFS(Recorder!$A:$A,$B$2,Recorder!$E:$E,$A42,Recorder!$G:$G,B$40,Recorder!$F:$F,$A$40,Recorder!$D:$D,$A$39) -> 0 | C42: =SUM(B42) -> 0
A43: Unsure | B43: =COUNTIFS(Recorder!$A:$A,$B$2,Recorder!$E:$E,$A43,Recorder!$G:$G,B$40,Recorder!$F:$F,$A$40,Recorder!$D:$D,$A$39) -> 0 | C43: =SUM(B43) -> 0
A44: Total | B44: =SUM(B41:B43) -> 0 | C44: =SUM(B44) -> 0
A46: PFC
A47: PL | B47: PFC layers | C47: Total
A48: Double | B48: =COUNTIFS(Recorder!$A:$A,$B$2,Recorder!$E:$E,$A48,Recorder!$G:$G,B$40,Recorder!$F:$F,$A$47,Recorder!$D:$D,$A$39) -> 13 | C48: =SUM(B48) -> 13
...

Sheet Atlas
A27: Brain Atlas
A56: Brain Atlas
